Traceback (most recent call last):
  File "/home/thomas/Notebook/anaconda/lib/python3.7/site-packages/jupyter_cache/executors/utils.py", line 56, in single_nb_execution
    record_timing=False,
  File "/home/thomas/Notebook/anaconda/lib/python3.7/site-packages/nbclient/client.py", line 1204, in execute
    return NotebookClient(nb=nb, resources=resources, km=km, **kwargs).execute()
  File "/home/thomas/Notebook/anaconda/lib/python3.7/site-packages/nbclient/util.py", line 84, in wrapped
    return just_run(coro(*args, **kwargs))
  File "/home/thomas/Notebook/anaconda/lib/python3.7/site-packages/nbclient/util.py", line 62, in just_run
    return loop.run_until_complete(coro)
  File "/home/thomas/Notebook/anaconda/lib/python3.7/asyncio/base_events.py", line 587, in run_until_complete
    return future.result()
  File "/home/thomas/Notebook/anaconda/lib/python3.7/site-packages/nbclient/client.py", line 664, in async_execute
    cell, index, execution_count=self.code_cells_executed + 1
  File "/home/thomas/Notebook/anaconda/lib/python3.7/site-packages/nbclient/client.py", line 965, in async_execute_cell
    await self._check_raise_for_error(cell, cell_index, exec_reply)
  File "/home/thomas/Notebook/anaconda/lib/python3.7/site-packages/nbclient/client.py", line 862, in _check_raise_for_error
    raise CellExecutionError.from_cell_and_msg(cell, exec_reply_content)
nbclient.exceptions.CellExecutionError: An error occurred while executing the following cell:
------------------
# molecule and basis

mol_xyz = """12
c2h4-dimer
C         -1.37731        1.01769       -0.71611
C         -0.04211        1.07142       -0.72602
H         -1.96225        1.74636       -0.16458
H         -1.90859        0.23094       -1.24174
H          0.49049        1.84498       -0.18262
H          0.54315        0.32947       -1.25941
C         -1.17537       -1.48468        2.37427
C          0.06813       -1.06658        2.62697
H         -1.35657       -2.40378        1.82687
H          0.92893       -1.63558        2.29127
H         -2.03527       -0.90348        2.69157
H          0.24803       -0.13578        3.15527
"""
molecule = vlx.Molecule.from_xyz_string(mol_xyz)
basis = vlx.MolecularBasis.read(molecule, 'def2-svp')
------------------

[0;31m---------------------------------------------------------------------------[0m
[0;31mAttributeError[0m                            Traceback (most recent call last)
[0;32m/tmp/ipykernel_12878/2327236284.py[0m in [0;36m<module>[0;34m[0m
[1;32m     16[0m [0mH[0m          [0;36m0.24803[0m       [0;34m-[0m[0;36m0.13578[0m        [0;36m3.15527[0m[0;34m[0m[0;34m[0m[0m
[1;32m     17[0m """
[0;32m---> 18[0;31m [0mmolecule[0m [0;34m=[0m [0mvlx[0m[0;34m.[0m[0mMolecule[0m[0;34m.[0m[0mfrom_xyz_string[0m[0;34m([0m[0mmol_xyz[0m[0;34m)[0m[0;34m[0m[0;34m[0m[0m
[0m[1;32m     19[0m [0mbasis[0m [0;34m=[0m [0mvlx[0m[0;34m.[0m[0mMolecularBasis[0m[0;34m.[0m[0mread[0m[0;34m([0m[0mmolecule[0m[0;34m,[0m [0;34m'def2-svp'[0m[0;34m)[0m[0;34m[0m[0;34m[0m[0m

[0;31mAttributeError[0m: type object 'veloxchem.veloxchemlib.Molecule' has no attribute 'from_xyz_string'
AttributeError: type object 'veloxchem.veloxchemlib.Molecule' has no attribute 'from_xyz_string'

