Traceback (most recent call last):
  File "/opt/miniconda3/envs/echem/lib/python3.7/site-packages/jupyter_cache/executors/utils.py", line 56, in single_nb_execution
    record_timing=False,
  File "/opt/miniconda3/envs/echem/lib/python3.7/site-packages/nbclient/client.py", line 1204, in execute
    return NotebookClient(nb=nb, resources=resources, km=km, **kwargs).execute()
  File "/opt/miniconda3/envs/echem/lib/python3.7/site-packages/nbclient/util.py", line 84, in wrapped
    return just_run(coro(*args, **kwargs))
  File "/opt/miniconda3/envs/echem/lib/python3.7/site-packages/nbclient/util.py", line 62, in just_run
    return loop.run_until_complete(coro)
  File "/opt/miniconda3/envs/echem/lib/python3.7/asyncio/base_events.py", line 587, in run_until_complete
    return future.result()
  File "/opt/miniconda3/envs/echem/lib/python3.7/site-packages/nbclient/client.py", line 664, in async_execute
    cell, index, execution_count=self.code_cells_executed + 1
  File "/opt/miniconda3/envs/echem/lib/python3.7/site-packages/nbclient/client.py", line 965, in async_execute_cell
    await self._check_raise_for_error(cell, cell_index, exec_reply)
  File "/opt/miniconda3/envs/echem/lib/python3.7/site-packages/nbclient/client.py", line 862, in _check_raise_for_error
    raise CellExecutionError.from_cell_and_msg(cell, exec_reply_content)
nbclient.exceptions.CellExecutionError: An error occurred while executing the following cell:
------------------
origin = np.zeros((n,3))

two_part_den_aa = vis_drv.get_two_particle_density(origin, coords, molecule, basis,
                                               density, 0, 'alpha', 'alpha')
two_part_den_ab = vis_drv.get_two_particle_density(origin, coords, molecule, basis,
                                               density, 0, 'alpha', 'beta')
------------------

[0;31m---------------------------------------------------------------------------[0m
[0;31mNameError[0m                                 Traceback (most recent call last)
[0;32m/var/folders/ky/5h8mb6gs32nbvf3w8cyqwrhm0000gn/T/ipykernel_2642/1033442239.py[0m in [0;36m<module>[0;34m[0m
[1;32m      2[0m [0;34m[0m[0m
[1;32m      3[0m two_part_den_aa = vis_drv.get_two_particle_density(origin, coords, molecule, basis,
[0;32m----> 4[0;31m                                                density, 0, 'alpha', 'alpha')
[0m[1;32m      5[0m two_part_den_ab = vis_drv.get_two_particle_density(origin, coords, molecule, basis,
[1;32m      6[0m                                                density, 0, 'alpha', 'beta')

[0;31mNameError[0m: name 'density' is not defined
NameError: name 'density' is not defined

