Traceback (most recent call last):
  File "/home/thomas/Notebook/anaconda/envs/echem/lib/python3.9/site-packages/jupyter_cache/executors/utils.py", line 51, in single_nb_execution
    executenb(
  File "/home/thomas/Notebook/anaconda/envs/echem/lib/python3.9/site-packages/nbclient/client.py", line 1117, in execute
    return NotebookClient(nb=nb, resources=resources, km=km, **kwargs).execute()
  File "/home/thomas/Notebook/anaconda/envs/echem/lib/python3.9/site-packages/nbclient/util.py", line 78, in wrapped
    return just_run(coro(*args, **kwargs))
  File "/home/thomas/Notebook/anaconda/envs/echem/lib/python3.9/site-packages/nbclient/util.py", line 57, in just_run
    return loop.run_until_complete(coro)
  File "/home/thomas/Notebook/anaconda/envs/echem/lib/python3.9/asyncio/base_events.py", line 642, in run_until_complete
    return future.result()
  File "/home/thomas/Notebook/anaconda/envs/echem/lib/python3.9/site-packages/nbclient/client.py", line 558, in async_execute
    await self.async_execute_cell(
  File "/home/thomas/Notebook/anaconda/envs/echem/lib/python3.9/site-packages/nbclient/client.py", line 862, in async_execute_cell
    self._check_raise_for_error(cell, exec_reply)
  File "/home/thomas/Notebook/anaconda/envs/echem/lib/python3.9/site-packages/nbclient/client.py", line 765, in _check_raise_for_error
    raise CellExecutionError.from_cell_and_msg(cell, exec_reply_content)
nbclient.exceptions.CellExecutionError: An error occurred while executing the following cell:
------------------
water_geom = """
O       0.0000000000     0.1187290000     0.0000000000
H      -0.7532010000    -0.4749160000    -0.0000000000
H       0.7532010000    -0.4749160000     0.0000000000
"""

# Prepare molecule object
mol       = gto.Mole()
mol.atom  = water_geom
mol.basis = '6-31G'
mol.build()

# SCF calculation
scf_gs = scf.HF(mol)
scf_gs.kernel()

# ADC(2) calculation, two states
adc_state = adcc.adc2(scf_gs,n_singlets=2)

# Print results
print(adc_state.describe())

# Print dominant amplitudes
print(adc_state.describe_amplitudes())
------------------

[0;31m---------------------------------------------------------------------------[0m
[0;31mNameError[0m                                 Traceback (most recent call last)
[0;32m/tmp/ipykernel_11591/1055689589.py[0m in [0;36m<module>[0;34m[0m
[1;32m      6[0m [0;34m[0m[0m
[1;32m      7[0m [0;31m# Prepare molecule object[0m[0;34m[0m[0;34m[0m[0m
[0;32m----> 8[0;31m [0mmol[0m       [0;34m=[0m [0mgto[0m[0;34m.[0m[0mMole[0m[0;34m([0m[0;34m)[0m[0;34m[0m[0;34m[0m[0m
[0m[1;32m      9[0m [0mmol[0m[0;34m.[0m[0matom[0m  [0;34m=[0m [0mwater_geom[0m[0;34m[0m[0;34m[0m[0m
[1;32m     10[0m [0mmol[0m[0;34m.[0m[0mbasis[0m [0;34m=[0m [0;34m'6-31G'[0m[0;34m[0m[0;34m[0m[0m

[0;31mNameError[0m: name 'gto' is not defined
NameError: name 'gto' is not defined

